<?xml version="1.0" encoding="UTF-8"?>
<testng-results skipped="0" failed="1" ignored="0" total="1" passed="0">
  <reporter-output>
  </reporter-output>
  <suite name="Default suite" duration-ms="8320" started-at="2022-11-21T17:13:10 CLST" finished-at="2022-11-21T17:13:18 CLST">
    <groups>
    </groups>
    <test name="Default test" duration-ms="8320" started-at="2022-11-21T17:13:10 CLST" finished-at="2022-11-21T17:13:18 CLST">
      <class name="cl.local.test.EliminarIncidencia">
        <test-method status="PASS" signature="setUp()[pri:0, instance:cl.local.test.EliminarIncidencia@32464a14]" name="setUp" is-config="true" duration-ms="2888" started-at="2022-11-21T17:13:10 CLST" finished-at="2022-11-21T17:13:12 CLST">
          <reporter-output>
          </reporter-output>
        </test-method> <!-- setUp -->
        <test-method status="FAIL" signature="eliminarIncidencia()[pri:0, instance:cl.local.test.EliminarIncidencia@32464a14]" name="eliminarIncidencia" duration-ms="5408" started-at="2022-11-21T17:13:13 CLST" finished-at="2022-11-21T17:13:18 CLST">
          <exception class="java.lang.AssertionError">
            <message>
              <![CDATA[No se encuetran incidencias declaradas]]>
            </message>
            <full-stacktrace>
              <![CDATA[java.lang.AssertionError: No se encuetran incidencias declaradas
at org.testng.Assert.fail(Assert.java:99)
at cl.local.test.EliminarIncidencia.eliminarIncidencia(EliminarIncidencia.java:24)
at sun.reflect.NativeMethodAccessorImpl.invoke0(Native Method)
at sun.reflect.NativeMethodAccessorImpl.invoke(Unknown Source)
at sun.reflect.DelegatingMethodAccessorImpl.invoke(Unknown Source)
at java.lang.reflect.Method.invoke(Unknown Source)
at org.testng.internal.MethodInvocationHelper.invokeMethod(MethodInvocationHelper.java:133)
at org.testng.internal.TestInvoker.invokeMethod(TestInvoker.java:598)
at org.testng.internal.TestInvoker.invokeTestMethod(TestInvoker.java:173)
at org.testng.internal.MethodRunner.runInSequence(MethodRunner.java:46)
at org.testng.internal.TestInvoker$MethodInvocationAgent.invoke(TestInvoker.java:824)
at org.testng.internal.TestInvoker.invokeTestMethods(TestInvoker.java:146)
at org.testng.internal.TestMethodWorker.invokeTestMethods(TestMethodWorker.java:146)
at org.testng.internal.TestMethodWorker.run(TestMethodWorker.java:128)
at java.util.ArrayList.forEach(Unknown Source)
at org.testng.TestRunner.privateRun(TestRunner.java:794)
at org.testng.TestRunner.run(TestRunner.java:596)
at org.testng.SuiteRunner.runTest(SuiteRunner.java:377)
at org.testng.SuiteRunner.runSequentially(SuiteRunner.java:371)
at org.testng.SuiteRunner.privateRun(SuiteRunner.java:332)
at org.testng.SuiteRunner.run(SuiteRunner.java:276)
at org.testng.SuiteRunnerWorker.runSuite(SuiteRunnerWorker.java:53)
at org.testng.SuiteRunnerWorker.run(SuiteRunnerWorker.java:96)
at org.testng.TestNG.runSuitesSequentially(TestNG.java:1212)
at org.testng.TestNG.runSuitesLocally(TestNG.java:1134)
at org.testng.TestNG.runSuites(TestNG.java:1063)
at org.testng.TestNG.run(TestNG.java:1031)
at org.testng.remote.AbstractRemoteTestNG.run(AbstractRemoteTestNG.java:115)
at org.testng.remote.RemoteTestNG.initAndRun(RemoteTestNG.java:251)
at org.testng.remote.RemoteTestNG.main(RemoteTestNG.java:77)
]]>
            </full-stacktrace>
          </exception> <!-- java.lang.AssertionError -->
          <reporter-output>
          </reporter-output>
        </test-method> <!-- eliminarIncidencia -->
        <test-method status="PASS" signature="tearDown()[pri:0, instance:cl.local.test.EliminarIncidencia@32464a14]" name="tearDown" is-config="true" duration-ms="390" started-at="2022-11-21T17:13:18 CLST" finished-at="2022-11-21T17:13:18 CLST">
          <reporter-output>
          </reporter-output>
        </test-method> <!-- tearDown -->
      </class> <!-- cl.local.test.EliminarIncidencia -->
    </test> <!-- Default test -->
  </suite> <!-- Default suite -->
</testng-results>
